Traceback (most recent call last):
  File "<frozen runpy>", line 198, in _run_module_as_main
  File "<frozen runpy>", line 88, in _run_code
  File "/app/routers/mcp/main.py", line 41, in <module>
    mcp.run(host="0.0.0.0", port=5510)
  File "/usr/local/lib/python3.11/site-packages/fastmcp/server/server.py", line 244, in run
    anyio.run(partial(self.run_async, transport, **transport_kwargs))
  File "/usr/local/lib/python3.11/site-packages/anyio/_core/_eventloop.py", line 74, in run
    return async_backend.run(func, args, {}, backend_options)
           ^^^^^^^^^^^^^^^^^^^^^^^^^^^^^^^^^^^^^^^^^^^^^^^^^^
  File "/usr/local/lib/python3.11/site-packages/anyio/_backends/_asyncio.py", line 2310, in run
    return runner.run(wrapper())
           ^^^^^^^^^^^^^^^^^^^^^
  File "/usr/local/lib/python3.11/asyncio/runners.py", line 118, in run
    return self._loop.run_until_complete(task)
           ^^^^^^^^^^^^^^^^^^^^^^^^^^^^^^^^^^^
  File "/usr/local/lib/python3.11/asyncio/base_events.py", line 654, in run_until_complete
    return future.result()
           ^^^^^^^^^^^^^^^
  File "/usr/local/lib/python3.11/site-packages/anyio/_backends/_asyncio.py", line 2298, in wrapper
    return await func(*args)
           ^^^^^^^^^^^^^^^^^
  File "/usr/local/lib/python3.11/site-packages/fastmcp/server/server.py", line 227, in run_async
    await self.run_stdio_async(**transport_kwargs)
          ^^^^^^^^^^^^^^^^^^^^^^^^^^^^^^^^^^^^^^^^
TypeError: FastMCP.run_stdio_async() got an unexpected keyword argument 'host'
